<?xml version="1.0"?>
<robot name="rover" xmlns:xacro="http://ros.org/wiki/xacro">
  
  <link name="base_link">
    <visual><geometry><box size="0.6 0.4 0.2"/></geometry></visual>
    <collision><geometry><box size="0.6 0.4 0.2"/></geometry></collision>
    <inertial><mass value="10.0"/><inertia ixx="0.1" ixy="0" ixz="0" iyy="0.1" iyz="0" izz="0.1"/></inertial>
  </link>

  <xacro:macro name="wheel" params="prefix x y">
    <link name="${prefix}_wheel">
      <visual><geometry><cylinder radius="0.1" length="0.05"/></geometry></visual>
      <collision><geometry><cylinder radius="0.1" length="0.05"/></geometry></collision>
      <inertial><mass value="1.0"/><inertia ixx="0.01" ixy="0" ixz="0" iyy="0.01" iyz="0" izz="0.01"/></inertial>
    </link>
    <joint name="${prefix}_wheel_joint" type="continuous">
      <parent link="base_link"/>
      <child link="${prefix}_wheel"/>
      <origin xyz="${x} ${y} -0.1" rpy="-1.5708 0 0"/>
      <axis xyz="0 0 1"/>
    </joint>
  </xacro:macro>

  <xacro:wheel prefix="fl" x="0.25" y="0.25"/>
  <xacro:wheel prefix="fr" x="0.25" y="-0.25"/>
  <xacro:wheel prefix="ml" x="0.0" y="0.25"/>
  <xacro:wheel prefix="mr" x="0.0" y="-0.25"/>
  <xacro:wheel prefix="rl" x="-0.25" y="0.25"/>
  <xacro:wheel prefix="rr" x="-0.25" y="-0.25"/>

  <link name="camera_link">
    <visual><geometry><box size="0.03 0.12 0.03"/></geometry></visual>
  </link>
  <joint name="camera_joint" type="fixed">
    <parent link="base_link"/>
    <child link="camera_link"/>
    <origin xyz="0.3 0 0.1" rpy="0 0 0"/>
  </joint>

  <link name="camera_depth_frame"/>
  <joint name="camera_optical_joint" type="fixed">
    <parent link="camera_link"/>
    <child link="camera_depth_frame"/>
    <origin xyz="0 0 0" rpy="-1.5708 0 -1.5708"/>
  </joint>
</robot>